Workbook
Name TableName: "Dummy"

Sheet plot_example
B1: cfs | E1: cfs | H1: OMR = -6250 | Q1: OMR = -5000 | Z1: OMR = -3500 | AL1: OMR = -2000 | AR1: tpp/ccf | AS1: 6250 | AT1: 5000 | AU1: 3250 | AV1: 2000
B2: FPT | C2: FPT Measured | D2: FPT Forecast | E2: VNS | F2: VNS Measured | G2: VNS Forecast | H2: OMR (cfs) | K2: CCF (af) | N2: TPP (af) | Q2: OMR (cfs) | T2: CCF (af) | W2: TPP (af) | Z2: OMR (cfs) | AC2: CCF (af) | AF2: TPP (af) | AI2: OMR (cfs) | AL2: CCF (af) | AO2: TPP (af)
A3: 46028 | B3: =INDEX('01_05_OMRI -2000'!$E$4:$E$393,MATCH($A3,'01_05_OMRI -2000'!$A$4:$A$393,0)) -> 75675 | C3: =B3 -> 75675 | E3: =INDEX('01_05_OMRI -2000'!$D$4:$D$393,MATCH($A3,'01_05_OMRI -2000'!$A$4:$A$393,0)) -> 5083 | F3: =E3 -> 5083 | H3: =-6250 -> -6250 | I3: =H3 -> -6250 | K3: =INDEX('01_05_OMRI -6250'!$B4:$B400,MATCH($A3,'01_05_OMRI -6250'!$A4:$A400,0)) -> 7600 | L3: =K3 -> 7600 | N3: =INDEX('01_05_OMRI -6250'!$C4:$C400,MATCH($A3,'01_05_OMRI -6250'!$A4:$A400,0)) -> 8800 | O3: =N3 -> 8800 | Q3: -5000 | R3: =Q3 -> -5000 | T3: =INDEX('01_05_OMRI -5000'!$B4:$B393,MATCH($A3,'01_05_OMRI -5000'!$A4:$A393,0)) -> 6347 | U3: =T3 -> 6347 | W3: =INDEX('01_05_OMRI -5000'!$C4:$C393,MATCH($A3,'01_05_OMRI -5000'!$A4:$A393,0)) -> 6942 | X3: =W3 -> 6942 | Z3: -3500 | AA3: =Z3 -> -3500 | AC3: =INDEX('01_05_OMRI -3500'!$B4:$B393,MATCH($A3,'01_05_OMRI -3500'!$A4:$A393,0)) -> 4760 | AD3: =AC3 -> 4760 | AF3: =INDEX('01_05_OMRI -3500'!$C4:$C393,MATCH($A3,'01_05_OMRI -3500'!$A4:$A393,0)) -> 6942 | AG3: =AF3 -> 6942 | AI3: -2000 | AJ3: =AI3 -> -2000 | AL3: =INDEX('01_05_OMRI -2000'!$B4:$B393,MATCH($A3,'01_05_OMRI -2000'!$A4:$A393,0)) -> 3372 | AM3: =AL3 -> 3372 | AO3: =INDEX('01_05_OMRI -2000'!$C4:$C393,MATCH($A3,'01_05_OMRI -2000'!$A4:$A393,0)) -> 6942 | AP3: =AO3 -> 6942 | AS3: =N3/(K3+N3) -> 0.53658537 | AT3: =W3/(T3+W3) -> 0.52238694 | AU3: =AF3/(AC3+AF3) -> 0.59323193 | AV3: =AO3/(AL3+AO3) -> 0.67306574
A4: =A3+1 -> 46029 | B4: =INDEX('01_05_OMRI -2000'!$E$4:$E$393,MATCH($A4,'01_05_OMRI -2000'!$A$4:$A$393,0)) -> 75866 | C4: =B4 -> 75866 | E4: =INDEX('01_05_OMRI -2000'!$D$4:$D$393,MATCH($A4,'01_05_OMRI -2000'!$A$4:$A$393,0)) -> 4454 | F4: =E4 -> 4454 | H4: =-6250 -> -6250 | I4: =H4 -> -6250 | K4: =INDEX('01_05_OMRI -6250'!$B5:$B401,MATCH($A4,'01_05_OMRI -6250'!$A5:$A401,0)) -> 9800 | L4: =K4 -> 9800 | N4: =INDEX('01_05_OMRI -6250'!$C5:$C401,MATCH($A4,'01_05_OMRI -6250'!$A5:$A401,0)) -> 9124 | O4: =N4 -> 9124 | Q4: -5000 | R4: =Q4 -> -5000 | T4: =INDEX('01_05_OMRI -5000'!$B4:$B394,MATCH($A4,'01_05_OMRI -5000'!$A4:$A394,0)) -> 7537 | U4: =T4 -> 7537 | W4: =INDEX('01_05_OMRI -5000'!$C4:$C394,MATCH($A4,'01_05_OMRI -5000'!$A4:$A394,0)) -> 8331 | X4: =W4 -> 8331 | Z4: -3500 | AA4: =Z4 -> -3500 | AC4: =INDEX('01_05_OMRI -3500'!$B4:$B394,MATCH($A4,'01_05_OMRI -3500'!$A4:$A394,0)) -> 5951 | AD4: =AC4 -> 5951 | AF4: =INDEX('01_05_OMRI -3500'!$C4:$C394,MATCH($A4,'01_05_OMRI -3500'!$A4:$A394,0)) -> 6942 | AG4: =AF4 -> 6942 | AI4: -2000 | AJ4: =AI4 -> -2000 | AL4: =INDEX('01_05_OMRI -2000'!$B4:$B394,MATCH($A4,'01_05_OMRI -2000'!$A4:$A394,0)) -> 4165 | AM4: =AL4 -> 4165 | AO4: =INDEX('01_05_OMRI -2000'!$C4:$C394,MATCH($A4,'01_05_OMRI -2000'!$A4:$A394,0)) -> 5355 | AP4: =AO4 -> 5355 | AS4: =N4/(K4+N4) -> 0.48213908 | AT4: =W4/(T4+W4) -> 0.52501891 | AU4: =AF4/(AC4+AF4) -> 0.53843171 | AV4: =AO4/(AL4+AO4) -> 0.5625
A5: =A4+1 -> 46030 | B5: =INDEX('01_05_OMRI -2000'!$E$4:$E$393,MATCH($A5,'01_05_OMRI -2000'!$A$4:$A$393,0)) -> 74302 | C5: =B5 -> 74302 | E5: =INDEX('01_05_OMRI -2000'!$D$4:$D$393,MATCH($A5,'01_05_OMRI -2000'!$A$4:$A$393,0)) -> 3541 | F5: =E5 -> 3541 | H5: =-6250 -> -6250 | I5: =H5 -> -6250 | K5: =INDEX('01_05_OMRI -6250'!$B6:$B402,MATCH($A5,'01_05_OMRI -6250'!$A6:$A402,0)) -> 8300 | L5: =K5 -> 8300 | N5: =INDEX('01_05_OMRI -6250'!$C6:$C402,MATCH($A5,'01_05_OMRI -6250'!$A6:$A402,0)) -> 9124 | O5: =N5 -> 9124 | Q5: -5000 | R5: =Q5 -> -5000 | T5: =INDEX('01_05_OMRI -5000'!$B4:$B395,MATCH($A5,'01_05_OMRI -5000'!$A4:$A395,0)) -> 6149 | U5: =T5 -> 6149 | W5: =INDEX('01_05_OMRI -5000'!$C4:$C395,MATCH($A5,'01_05_OMRI -5000'!$A4:$A395,0)) -> 8331 | X5: =W5 -> 8331 | Z5: -3500 | AA5: =Z5 -> -3500 | AC5: =INDEX('01_05_OMRI -3500'!$B4:$B395,MATCH($A5,'01_05_OMRI -3500'!$A4:$A395,0)) -> 4165 | AD5: =AC5 -> 4165 | AF5: =INDEX('01_05_OMRI -3500'!$C4:$C395,MATCH($A5,'01_05_OMRI -3500'!$A4:$A395,0)) -> 6942 | AG5: =AF5 -> 6942 | AI5: -2000 | AJ5: =AI5 -> -2000 | AL5: =INDEX('01_05_OMRI -2000'!$B4:$B395,MATCH($A5,'01_05_OMRI -2000'!$A4:$A395,0)) -> 4364 | AM5: =AL5 -> 4364 | AO5: =INDEX('01_05_OMRI -2000'!$C4:$C395,MATCH($A5,'01_05_OMRI -2000'!$A4:$A395,0)) -> 3570 | AP5: =AO5 -> 3570 | AS5: =N5/(K5+N5) -> 0.52364555 | AT5: =W5/(T5+W5) -> 0.5753453 | AU5: =AF5/(AC5+AF5) -> 0.62501125 | AV5: =AO5/(AL5+AO5) -> 0.44996219
A6: =A5+1 -> 46031 | B6: =INDEX('01_05_OMRI -2000'!$E$4:$E$393,MATCH($A6,'01_05_OMRI -2000'!$A$4:$A$393,0)) -> 73450 | C6: =B6 -> 73450 | E6: =INDEX('01_05_OMRI -2000'!$D$4:$D$393,MATCH($A6,'01_05_OMRI -2000'!$A$4:$A$393,0)) -> 3237 | F6: =E6 -> 3237 | H6: =-6250 -> -6250 | I6: =H6 -> -6250 | K6: =INDEX('01_05_OMRI -6250'!$B7:$B403,MATCH($A6,'01_05_OMRI -6250'!$A7:$A403,0)) -> 7400 | L6: =K6 -> 7400 | N6: =INDEX('01_05_OMRI -6250'!$C7:$C403,MATCH($A6,'01_05_OMRI -6250'!$A7:$A403,0)) -> 9124 | O6: =N6 -> 9124 | Q6: -5000 | R6: =Q6 -> -5000 | T6: =INDEX('01_05_OMRI -5000'!$B4:$B396,MATCH($A6,'01_05_OMRI -5000'!$A4:$A396,0)) -> 5355 | U6: =T6 -> 5355 | W6: =INDEX('01_05_OMRI -5000'!$C4:$C396,MATCH($A6,'01_05_OMRI -5000'!$A4:$A396,0)) -> 8331 | X6: =W6 -> 8331 | Z6: -3500 | AA6: =Z6 -> -3500 | AC6: =INDEX('01_05_OMRI -3500'!$B4:$B396,MATCH($A6,'01_05_OMRI -3500'!$A4:$A396,0)) -> 4959 | AD6: =AC6 -> 4959 | AF6: =INDEX('01_05_OMRI -3500'!$C4:$C396,MATCH($A6,'01_05_OMRI -3500'!$A4:$A396,0)) -> 5355 | AG6: =AF6 -> 5355 | AI6: -2000 | AJ6: =AI6 -> -2000 | AL6: =INDEX('01_05_OMRI -2000'!$B4:$B396,MATCH($A6,'01_05_OMRI -2000'!$A4:$A396,0)) -> 3570 | AM6: =AL6 -> 3570 | AO6: =INDEX('01_05_OMRI -2000'!$C4:$C396,MATCH($A6,'01_05_OMRI -2000'!$A4:$A396,0)) -> 3570 | AP6: =AO6 -> 3570 | AS6: =N6/(K6+N6) -> 0.55216655 | AT6: =W6/(T6+W6) -> 0.60872424 | AU6: =AF6/(AC6+AF6) -> 0.51919721 | AV6: =AO6/(AL6+AO6) -> 0.5
A7: =A6+1 -> 46032 | B7: =INDEX('01_05_OMRI -2000'!$E$4:$E$393,MATCH($A7,'01_05_OMRI -2000'!$A$4:$A$393,0)) -> 72041 | C7: =B7 -> 72041 | E7: =INDEX('01_05_OMRI -2000'!$D$4:$D$393,MATCH($A7,'01_05_OMRI -2000'!$A$4:$A$393,0)) -> 3124 | F7: =E7 -> 3124 | H7: =-6250 -> -6250 | I7: =H7 -> -6250 | K7: =INDEX('01_05_OMRI -6250'!$B8:$B404,MATCH($A7,'01_05_OMRI -6250'!$A8:$A404,0)) -> 7100 | L7: =K7 -> 7100 | N7: =INDEX('01_05_OMRI -6250'!$C8:$C404,MATCH($A7,'01_05_OMRI -6250'!$A8:$A404,0)) -> 9124 | O7: =N7 -> 9124 | Q7: -5000 | R7: =Q7 -> -5000 | T7: =INDEX('01_05_OMRI -5000'!$B4:$B397,MATCH($A7,'01_05_OMRI -5000'!$A4:$A397,0)) -> 6347 | U7: =T7 -> 6347 | W7: =INDEX('01_05_OMRI -5000'!$C4:$C397,MATCH($A7,'01_05_OMRI -5000'!$A4:$A397,0)) -> 6942 | X7: =W7 -> 6942 | Z7: -3500 | AA7: =Z7 -> -3500 | AC7: =INDEX('01_05_OMRI -3500'!$B4:$B397,MATCH($A7,'01_05_OMRI -3500'!$A4:$A397,0)) -> 4562 | AD7: =AC7 -> 4562 | AF7: =INDEX('01_05_OMRI -3500'!$C4:$C397,MATCH($A7,'01_05_OMRI -3500'!$A4:$A397,0)) -> 5355 | AG7: =AF7 -> 5355 | AI7: -2000 | AJ7: =AI7 -> -2000 | AL7: =INDEX('01_05_OMRI -2000'!$B4:$B397,MATCH($A7,'01_05_OMRI -2000'!$A4:$A397,0)) -> 3174 | AM7: =AL7 -> 3174 | AO7: =INDEX('01_05_OMRI -2000'!$C4:$C397,MATCH($A7,'01_05_OMRI -2000'!$A4:$A397,0)) -> 3570 | AP7: =AO7 -> 3570 | AS7: =N7/(K7+N7) -> 0.56237673 | AT7: =W7/(T7+W7) -> 0.52238694 | AU7: =AF7/(AC7+AF7) -> 0.53998185 | AV7: =AO7/(AL7+AO7) -> 0.52935943
A8: =A7+1 -> 46033 | B8: =INDEX('01_05_OMRI -2000'!$E$4:$E$393,MATCH($A8,'01_05_OMRI -2000'!$A$4:$A$393,0)) -> 70572 | C8: =B8 -> 70572 | D8: =C8 -> 70572 | E8: =INDEX('01_05_OMRI -2000'!$D$4:$D$393,MATCH($A8,'01_05_OMRI -2000'!$A$4:$A$393,0)) -> 2973 | F8: =E8 -> 2973 | G8: =E8 -> 2973 | H8: =-6250 -> -6250 | I8: =H8 -> -6250 | J8: =H8 -> -6250 | K8: =INDEX('01_05_OMRI -6250'!$B9:$B405,MATCH($A8,'01_05_OMRI -6250'!$A9:$A405,0)) -> 6500 | L8: =K8 -> 6500 | M8: =K8 -> 6500 | N8: =INDEX('01_05_OMRI -6250'!$C9:$C405,MATCH($A8,'01_05_OMRI -6250'!$A9:$A405,0)) -> 9124 | O8: =N8 -> 9124 | P8: =N8 -> 9124 | Q8: -5000 | R8: =Q8 -> -5000 | S8: =Q8 -> -5000 | T8: =INDEX('01_05_OMRI -5000'!$B4:$B398,MATCH($A8,'01_05_OMRI -5000'!$A4:$A398,0)) -> 5752 | U8: =T8 -> 5752 | V8: =T8 -> 5752 | W8: =INDEX('01_05_OMRI -5000'!$C4:$C398,MATCH($A8,'01_05_OMRI -5000'!$A4:$A398,0)) -> 6942 | X8: =W8 -> 6942 | Y8: =W8 -> 6942 | Z8: -3500 | AA8: =Z8 -> -3500 | AB8: =Z8 -> -3500 | AC8: =INDEX('01_05_OMRI -3500'!$B4:$B398,MATCH($A8,'01_05_OMRI -3500'!$A4:$A398,0)) -> 4165 | AD8: =AC8 -> 4165 | AE8: =AC8 -> 4165 | AF8: =INDEX('01_05_OMRI -3500'!$C4:$C398,MATCH($A8,'01_05_OMRI -3500'!$A4:$A398,0)) -> 5355 | AG8: =AF8 -> 5355 | AH8: =AF8 -> 5355 | AI8: -2000 | AJ8: =AI8 -> -2000 | AK8: =AI8 -> -2000 | AL8: =INDEX('01_05_OMRI -2000'!$B4:$B398,MATCH($A8,'01_05_OMRI -2000'!$A4:$A398,0)) -> 2579 | AM8: =AL8 -> 2579 | AN8: =AL8 -> 2579 | AO8: =INDEX('01_05_OMRI -2000'!$C4:$C398,MATCH($A8,'01_05_OMRI -2000'!$A4:$A398,0)) -> 3570 | AP8: =AO8 -> 3570 | AQ8: =AO8 -> 3570 | AS8: =N8/(K8+N8) -> 0.58397337 | AT8: =W8/(T8+W8) -> 0.54687254 | AU8: =AF8/(AC8+AF8) -> 0.5625 | AV8: =AO8/(AL8+AO8) -> 0.58058221
A9: =A8+1 -> 46034 | B9: =INDEX('01_05_OMRI -2000'!$E$4:$E$393,MATCH($A9,'01_05_OMRI -2000'!$A$4:$A$393,0)) -> 69004 | D9: =B9 -> 69004 | E9: =INDEX('01_05_OMRI -2000'!$D$4:$D$393,MATCH($A9,'01_05_OMRI -2000'!$A$4:$A$393,0)) -> 2724 | G9: =E9 -> 2724 | H9: =-6250 -> -6250 | J9: =H9 -> -6250 | K9: =INDEX('01_05_OMRI -6250'!$B10:$B406,MATCH($A9,'01_05_OMRI -6250'!$A10:$A406,0)) -> 6400 | M9: =K9 -> 6400 | N9: =INDEX('01_05_OMRI -6250'!$C10:$C406,MATCH($A9,'01_05_OMRI -6250'!$A10:$A406,0)) -> 8800 | P9: =N9 -> 8800 | Q9: -5000 | S9: =Q9 -> -5000 | T9: =INDEX('01_05_OMRI -5000'!$B4:$B399,MATCH($A9,'01_05_OMRI -5000'!$A4:$A399,0)) -> 5355 | V9: =T9 -> 5355 | W9: =INDEX('01_05_OMRI -5000'!$C4:$C399,MATCH($A9,'01_05_OMRI -5000'!$A4:$A399,0)) -> 6942 | Y9: =W9 -> 6942 | Z9: -3500 | AB9: =Z9 -> -3500 | AC9: =INDEX('01_05_OMRI -3500'!$B4:$B399,MATCH($A9,'01_05_OMRI -3500'!$A4:$A399,0)) -> 3570 | AE9: =AC9 -> 3570 | AF9: =INDEX('01_05_OMRI -3500'!$C4:$C399,MATCH($A9,'01_05_OMRI -3500'!$A4:$A399,0)) -> 5355 | AH9: =AF9 -> 5355 | AI9: -2000 | AK9: =AI9 -> -2000 | AL9: =INDEX('01_05_OMRI -2000'!$B4:$B399,MATCH($A9,'01_05_OMRI -2000'!$A4:$A399,0)) -> 2182 | AN9: =AL9 -> 2182 | AO9: =INDEX('01_05_OMRI -2000'!$C4:$C399,MATCH($A9,'01_05_OMRI -2000'!$A4:$A399,0)) -> 3570 | AQ9: =AO9 -> 3570 | AS9: =N9/(K9+N9) -> 0.57894737 | AT9: =W9/(T9+W9) -> 0.56452793 | AU9: =AF9/(AC9+AF9) -> 0.6 | AV9: =AO9/(AL9+AO9) -> 0.62065369
A10: =A9+1 -> 46035 | B10: =INDEX('01_05_OMRI -2000'!$E$4:$E$393,MATCH($A10,'01_05_OMRI -2000'!$A$4:$A$393,0)) -> 66245 | D10: =B10 -> 66245 | E10: =INDEX('01_05_OMRI -2000'!$D$4:$D$393,MATCH($A10,'01_05_OMRI -2000'!$A$4:$A$393,0)) -> 2551 | G10: =E10 -> 2551 | H10: =-6250 -> -6250 | J10: =H10 -> -6250 | K10: =INDEX('01_05_OMRI -6250'!$B11:$B407,MATCH($A10,'01_05_OMRI -6250'!$A11:$A407,0)) -> 6400 | M10: =K10 -> 6400 | N10: =INDEX('01_05_OMRI -6250'!$C11:$C407,MATCH($A10,'01_05_OMRI -6250'!$A11:$A407,0)) -> 8800 | P10: =N10 -> 8800 | Q10: -5000 | S10: =Q10 -> -5000 | T10: =INDEX('01_05_OMRI -5000'!$B4:$B400,MATCH($A10,'01_05_OMRI -5000'!$A4:$A400,0)) -> 5355 | V10: =T10 -> 5355 | W10: =INDEX('01_05_OMRI -5000'!$C4:$C400,MATCH($A10,'01_05_OMRI -5000'!$A4:$A400,0)) -> 6942 | Y10: =W10 -> 6942 | Z10: -3500 | AB10: =Z10 -> -3500 | AC10: =INDEX('01_05_OMRI -3500'!$B4:$B400,MATCH($A10,'01_05_OMRI -3500'!$A4:$A400,0)) -> 3570 | AE10: =AC10 -> 3570 | AF10: =INDEX('01_05_OMRI -3500'!$C4:$C400,MATCH($A10,'01_05_OMRI -3500'!$A4:$A400,0)) -> 5355 | AH10: =AF10 -> 5355 | AI10: -2000 | AK10: =AI10 -> -2000 | AL10: =INDEX('01_05_OMRI -2000'!$B4:$B400,MATCH($A10,'01_05_OMRI -2000'!$A4:$A400,0)) -> 2182 | AN10: =AL10 -> 2182 | AO10: =INDEX('01_05_OMRI -2000'!$C4:$C400,MATCH($A10,'01_05_OMRI -2000'!$A4:$A400,0)) -> 3570 | AQ10: =AO10 -> 3570 | AS10: =N10/(K10+N10) -> 0.57894737 | AT10: =W10/(T10+W10) -> 0.56452793 | AU10: =AF10/(AC10+AF10) -> 0.6 | AV10: =AO10/(AL10+AO10) -> 0.62065369
A11: =A10+1 -> 46036 | B11: =INDEX('01_05_OMRI -2000'!$E$4:$E$393,MATCH($A11,'01_05_OMRI -2000'!$A$4:$A$393,0)) -> 62756 | D11: =B11 -> 62756 | E11: =INDEX('01_05_OMRI -2000'!$D$4:$D$393,MATCH($A11,'01_05_OMRI -2000'!$A$4:$A$393,0)) -> 2551 | G11: =E11 -> 2551 | H11: =-6250 -> -6250 | J11: =H11 -> -6250 | K11: =INDEX('01_05_OMRI -6250'!$B12:$B408,MATCH($A11,'01_05_OMRI -6250'!$A12:$A408,0)) -> 6400 | M11: =K11 -> 6400 | N11: =INDEX('01_05_OMRI -6250'!$C12:$C408,MATCH($A11,'01_05_OMRI -6250'!$A12:$A408,0)) -> 8800 | P11: =N11 -> 8800 | Q11: -5000 | S11: =Q11 -> -5000 | T11: =INDEX('01_05_OMRI -5000'!$B5:$B401,MATCH($A11,'01_05_OMRI -5000'!$A5:$A401,0)) -> 5355 | V11: =T11 -> 5355 | W11: =INDEX('01_05_OMRI -5000'!$C5:$C401,MATCH($A11,'01_05_OMRI -5000'!$A5:$A401,0)) -> 6942 | Y11: =W11 -> 6942 | Z11: -3500 | AB11: =Z11 -> -3500 | AC11: =INDEX('01_05_OMRI -3500'!$B5:$B401,MATCH($A11,'01_05_OMRI -3500'!$A5:$A401,0)) -> 3570 | AE11: =AC11 -> 3570 | AF11: =INDEX('01_05_OMRI -3500'!$C5:$C401,MATCH($A11,'01_05_OMRI -3500'!$A5:$A401,0)) -> 5355 | AH11: =AF11 -> 5355 | AI11: -2000 | AK11: =AI11 -> -2000 | AL11: =INDEX('01_05_OMRI -2000'!$B5:$B401,MATCH($A11,'01_05_OMRI -2000'!$A5:$A401,0)) -> 2182 | AN11: =AL11 -> 2182 | AO11: =INDEX('01_05_OMRI -2000'!$C5:$C401,MATCH($A11,'01_05_OMRI -2000'!$A5:$A401,0)) -> 3570 | AQ11: =AO11 -> 3570 | AS11: =N11/(K11+N11) -> 0.57894737 | AT11: =W11/(T11+W11) -> 0.56452793 | AU11: =AF11/(AC11+AF11) -> 0.6 | AV11: =AO11/(AL11+AO11) -> 0.62065369
A12: =A11+1 -> 46037 | B12: =INDEX('01_05_OMRI -2000'!$E$4:$E$393,MATCH($A12,'01_05_OMRI -2000'!$A$4:$A$393,0)) -> 62756 | D12: =B12 -> 62756 | E12: =INDEX('01_05_OMRI -2000'!$D$4:$D$393,MATCH($A12,'01_05_OMRI -2000'!$A$4:$A$393,0)) -> 2551 | G12: =E12 -> 2551 | H12: =-6250 -> -6250 | J12: =H12 -> -6250 | K12: =INDEX('01_05_OMRI -6250'!$B13:$B409,MATCH($A12,'01_05_OMRI -6250'!$A13:$A409,0)) -> 6400 | M12: =K12 -> 6400 | N12: =INDEX('01_05_OMRI -6250'!$C13:$C409,MATCH($A12,'01_05_OMRI -6250'!$A13:$A409,0)) -> 8800 | P12: =N12 -> 8800 | Q12: -5000 | S12: =Q12 -> -5000 | T12: =INDEX('01_05_OMRI -5000'!$B6:$B402,MATCH($A12,'01_05_OMRI -5000'!$A6:$A402,0)) -> 5355 | V12: =T12 -> 5355 | W12: =INDEX('01_05_OMRI -5000'!$C6:$C402,MATCH($A12,'01_05_OMRI -5000'!$A6:$A402,0)) -> 6942 | Y12: =W12 -> 6942 | Z12: -3500 | AB12: =Z12 -> -3500 | AC12: =INDEX('01_05_OMRI -3500'!$B6:$B402,MATCH($A12,'01_05_OMRI -3500'!$A6:$A402,0)) -> 3570 | AE12: =AC12 -> 3570 | AF12: =INDEX('01_05_OMRI -3500'!$C6:$C402,MATCH($A12,'01_05_OMRI -3500'!$A6:$A402,0)) -> 5355 | AH12: =AF12 -> 5355 | AI12: -2000 | AK12: =AI12 -> -2000 | AL12: =INDEX('01_05_OMRI -2000'!$B6:$B402,MATCH($A12,'01_05_OMRI -2000'!$A6:$A402,0)) -> 2182 | AN12: =AL12 -> 2182 | AO12: =INDEX('01_05_OMRI -2000'!$C6:$C402,MATCH($A12,'01_05_OMRI -2000'!$A6:$A402,0)) -> 3570 | AQ12: =AO12 -> 3570 | AS12: =N12/(K12+N12) -> 0.57894737 | AT12: =W12/(T12+W12) -> 0.56452793 | AU12: =AF12/(AC12+AF12) -> 0.6 | AV12: =AO12/(AL12+AO12) -> 0.62065369
A13: =A12+1 -> 46038 | B13: =INDEX('01_05_OMRI -2000'!$E$4:$E$393,MATCH($A13,'01_05_OMRI -2000'!$A$4:$A$393,0)) -> 62756 | D13: =B13 -> 62756 | E13: =INDEX('01_05_OMRI -2000'!$D$4:$D$393,MATCH($A13,'01_05_OMRI -2000'!$A$4:$A$393,0)) -> 2552 | G13: =E13 -> 2552 | H13: =-6250 -> -6250 | J13: =H13 -> -6250 | K13: =INDEX('01_05_OMRI -6250'!$B14:$B410,MATCH($A13,'01_05_OMRI -6250'!$A14:$A410,0)) -> 6400 | M13: =K13 -> 6400 | N13: =INDEX('01_05_OMRI -6250'!$C14:$C410,MATCH($A13,'01_05_OMRI -6250'!$A14:$A410,0)) -> 8800 | P13: =N13 -> 8800 | Q13: -5000 | S13: =Q13 -> -5000 | T13: =INDEX('01_05_OMRI -5000'!$B7:$B403,MATCH($A13,'01_05_OMRI -5000'!$A7:$A403,0)) -> 5355 | V13: =T13 -> 5355 | W13: =INDEX('01_05_OMRI -5000'!$C7:$C403,MATCH($A13,'01_05_OMRI -5000'!$A7:$A403,0)) -> 6942 | Y13: =W13 -> 6942 | Z13: -3500 | AB13: =Z13 -> -3500 | AC13: =INDEX('01_05_OMRI -3500'!$B7:$B403,MATCH($A13,'01_05_OMRI -3500'!$A7:$A403,0)) -> 3570 | AE13: =AC13 -> 3570 | AF13: =INDEX('01_05_OMRI -3500'!$C7:$C403,MATCH($A13,'01_05_OMRI -3500'!$A7:$A403,0)) -> 5355 | AH13: =AF13 -> 5355 | AI13: -2000 | AK13: =AI13 -> -2000 | AL13: =INDEX('01_05_OMRI -2000'!$B7:$B403,MATCH($A13,'01_05_OMRI -2000'!$A7:$A403,0)) -> 2182 | AN13: =AL13 -> 2182 | AO13: =INDEX('01_05_OMRI -2000'!$C7:$C403,MATCH($A13,'01_05_OMRI -2000'!$A7:$A403,0)) -> 3570 | AQ13: =AO13 -> 3570 | AS13: =N13/(K13+N13) -> 0.57894737 | AT13: =W13/(T13+W13) -> 0.56452793 | AU13: =AF13/(AC13+AF13) -> 0.6 | AV13: =AO13/(AL13+AO13) -> 0.62065369
A14: =A13+1 -> 46039 | B14: =INDEX('01_05_OMRI -2000'!$E$4:$E$393,MATCH($A14,'01_05_OMRI -2000'!$A$4:$A$393,0)) -> 62756 | D14: =B14 -> 62756 | E14: =INDEX('01_05_OMRI -2000'!$D$4:$D$393,MATCH($A14,'01_05_OMRI -2000'!$A$4:$A$393,0)) -> 2552 | G14: =E14 -> 2552 | H14: =-6250 -> -6250 | J14: =H14 -> -6250 | K14: =INDEX('01_05_OMRI -6250'!$B15:$B411,MATCH($A14,'01_05_OMRI -6250'!$A15:$A411,0)) -> 6400 | M14: =K14 -> 6400 | N14: =INDEX('01_05_OMRI -6250'!$C15:$C411,MATCH($A14,'01_05_OMRI -6250'!$A15:$A411,0)) -> 8800 | P14: =N14 -> 8800 | Q14: -5000 | S14: =Q14 -> -5000 | T14: =INDEX('01_05_OMRI -5000'!$B8:$B404,MATCH($A14,'01_05_OMRI -5000'!$A8:$A404,0)) -> 5355 | V14: =T14 -> 5355 | W14: =INDEX('01_05_OMRI -5000'!$C8:$C404,MATCH($A14,'01_05_OMRI -5000'!$A8:$A404,0)) -> 6942 | Y14: =W14 -> 6942 | Z14: -3500 | AB14: =Z14 -> -3500 | AC14: =INDEX('01_05_OMRI -3500'!$B8:$B404,MATCH($A14,'01_05_OMRI -3500'!$A8:$A404,0)) -> 3570 | AE14: =AC14 -> 3570 | AF14: =INDEX('01_05_OMRI -3500'!$C8:$C404,MATCH($A14,'01_05_OMRI -3500'!$A8:$A404,0)) -> 5355 | AH14: =AF14 -> 5355 | AI14: -2000 | AK14: =AI14 -> -2000 | AL14: =INDEX('01_05_OMRI -2000'!$B8:$B404,MATCH($A14,'01_05_OMRI -2000'!$A8:$A404,0)) -> 2182 | AN14: =AL14 -> 2182 | AO14: =INDEX('01_05_OMRI -2000'!$C8:$C404,MATCH($A14,'01_05_OMRI -2000'!$A8:$A404,0)) -> 3570 | AQ14: =AO14 -> 3570 | AS14: =N14/(K14+N14) -> 0.57894737 | AT14: =W14/(T14+W14) -> 0.56452793 | AU14: =AF14/(AC14+AF14) -> 0.6 | AV14: =AO14/(AL14+AO14) -> 0.62065369
A15: =A14+1 -> 46040 | B15: =INDEX('01_05_OMRI -2000'!$E$4:$E$393,MATCH($A15,'01_05_OMRI -2000'!$A$4:$A$393,0)) -> 62756 | D15: =B15 -> 62756 | E15: =INDEX('01_05_OMRI -2000'!$D$4:$D$393,MATCH($A15,'01_05_OMRI -2000'!$A$4:$A$393,0)) -> 2553 | G15: =E15 -> 2553 | H15: =-6250 -> -6250 | J15: =H15 -> -6250 | K15: =INDEX('01_05_OMRI -6250'!$B16:$B412,MATCH($A15,'01_05_OMRI -6250'!$A16:$A412,0)) -> 6400 | M15: =K15 -> 6400 | N15: =INDEX('01_05_OMRI -6250'!$C16:$C412,MATCH($A15,'01_05_OMRI -6250'!$A16:$A412,0)) -> 8800 | P15: =N15 -> 8800 | Q15: -5000 | S15: =Q15 -> -5000 | T15: =INDEX('01_05_OMRI -5000'!$B9:$B405,MATCH($A15,'01_05_OMRI -5000'!$A9:$A405,0)) -> 5355 | V15: =T15 -> 5355 | W15: =INDEX('01_05_OMRI -5000'!$C9:$C405,MATCH($A15,'01_05_OMRI -5000'!$A9:$A405,0)) -> 6942 | Y15: =W15 -> 6942 | Z15: -3500 | AB15: =Z15 -> -3500 | AC15: =INDEX('01_05_OMRI -3500'!$B9:$B405,MATCH($A15,'01_05_OMRI -3500'!$A9:$A405,0)) -> 3570 | AE15: =AC15 -> 3570 | AF15: =INDEX('01_05_OMRI -3500'!$C9:$C405,MATCH($A15,'01_05_OMRI -3500'!$A9:$A405,0)) -> 5355 | AH15: =AF15 -> 5355 | AI15: -2000 | AK15: =AI15 -> -2000 | AL15: =INDEX('01_05_OMRI -2000'!$B9:$B405,MATCH($A15,'01_05_OMRI -2000'!$A9:$A405,0)) -> 2182 | AN15: =AL15 -> 2182 | AO15: =INDEX('01_05_OMRI -2000'!$C9:$C405,MATCH($A15,'01_05_OMRI -2000'!$A9:$A405,0)) -> 3570 | AQ15: =AO15 -> 3570 | AS15: =N15/(K15+N15) -> 0.57894737 | AT15: =W15/(T15+W15) -> 0.56452793 | AU15: =AF15/(AC15+AF15) -> 0.6 | AV15: =AO15/(AL15+AO15) -> 0.62065369
A16: =A15+1 -> 46041 | B16: =INDEX('01_05_OMRI -2000'!$E$4:$E$393,MATCH($A16,'01_05_OMRI -2000'!$A$4:$A$393,0)) -> 62756 | D16: =B16 -> 62756 | E16: =INDEX('01_05_OMRI -2000'!$D$4:$D$393,MATCH($A16,'01_05_OMRI -2000'!$A$4:$A$393,0)) -> 2553 | G16: =E16 -> 2553 | H16: =-6250 -> -6250 | J16: =H16 -> -6250 | K16: =INDEX('01_05_OMRI -6250'!$B17:$B413,MATCH($A16,'01_05_OMRI -6250'!$A17:$A413,0)) -> 6400 | M16: =K16 -> 6400 | N16: =INDEX('01_05_OMRI -6250'!$C17:$C413,MATCH($A16,'01_05_OMRI -6250'!$A17:$A413,0)) -> 8800 | P16: =N16 -> 8800 | Q16: -5000 | S16: =Q16 -> -5000 | T16: =INDEX('01_05_OMRI -5000'!$B10:$B406,MATCH($A16,'01_05_OMRI -5000'!$A10:$A406,0)) -> 5355 | V16: =T16 -> 5355 | W16: =INDEX('01_05_OMRI -5000'!$C10:$C406,MATCH($A16,'01_05_OMRI -5000'!$A10:$A406,0)) -> 6942 | Y16: =W16 -> 6942 | Z16: -3500 | AB16: =Z16 -> -3500 | AC16: =INDEX('01_05_OMRI -3500'!$B10:$B406,MATCH($A16,'01_05_OMRI -3500'!$A10:$A406,0)) -> 3570 | AE16: =AC16 -> 3570 | AF16: =INDEX('01_05_OMRI -3500'!$C10:$C406,MATCH($A16,'01_05_OMRI -3500'!$A10:$A406,0)) -> 5355 | AH16: =AF16 -> 5355 | AI16: -2000 | AK16: =AI16 -> -2000 | AL16: =INDEX('01_05_OMRI -2000'!$B10:$B406,MATCH($A16,'01_05_OMRI -2000'!$A10:$A406,0)) -> 2182 | AN16: =AL16 -> 2182 | AO16: =INDEX('01_05_OMRI -2000'!$C10:$C406,MATCH($A16,'01_05_OMRI -2000'!$A10:$A406,0)) -> 3570 | AQ16: =AO16 -> 3570 | AS16: =N16/(K16+N16) -> 0.57894737 | AT16: =W16/(T16+W16) -> 0.56452793 | AU16: =AF16/(AC16+AF16) -> 0.6 | AV16: =AO16/(AL16+AO16) -> 0.62065369
A17: =A16+1 -> 46042 | B17: =INDEX('01_05_OMRI -2000'!$E$4:$E$393,MATCH($A17,'01_05_OMRI -2000'!$A$4:$A$393,0)) -> 62756 | D17: =B17 -> 62756 | E17: =INDEX('01_05_OMRI -2000'!$D$4:$D$393,MATCH($A17,'01_05_OMRI -2000'!$A$4:$A$393,0)) -> 2553 | G17: =E17 -> 2553 | H17: =-6250 -> -6250 | J17: =H17 -> -6250 | K17: =INDEX('01_05_OMRI -6250'!$B18:$B414,MATCH($A17,'01_05_OMRI -6250'!$A18:$A414,0)) -> 6400 | M17: =K17 -> 6400 | N17: =INDEX('01_05_OMRI -6250'!$C18:$C414,MATCH($A17,'01_05_OMRI -6250'!$A18:$A414,0)) -> 8800 | P17: =N17 -> 8800 | Q17: -5000 | S17: =Q17 -> -5000 | T17: =INDEX('01_05_OMRI -5000'!$B11:$B407,MATCH($A17,'01_05_OMRI -5000'!$A11:$A407,0)) -> 5355 | V17: =T17 -> 5355 | W17: =INDEX('01_05_OMRI -5000'!$C11:$C407,MATCH($A17,'01_05_OMRI -5000'!$A11:$A407,0)) -> 6942 | Y17: =W17 -> 6942 | Z17: -3500 | AB17: =Z17 -> -3500 | AC17: =INDEX('01_05_OMRI -3500'!$B11:$B407,MATCH($A17,'01_05_OMRI -3500'!$A11:$A407,0)) -> 3570 | AE17: =AC17 -> 3570 | AF17: =INDEX('01_05_OMRI -3500'!$C11:$C407,MATCH($A17,'01_05_OMRI -3500'!$A11:$A407,0)) -> 5355 | AH17: =AF17 -> 5355 | AI17: -2000 | AK17: =AI17 -> -2000 | AL17: =INDEX('01_05_OMRI -2000'!$B11:$B407,MATCH($A17,'01_05_OMRI -2000'!$A11:$A407,0)) -> 2182 | AN17: =AL17 -> 2182 | AO17: =INDEX('01_05_OMRI -2000'!$C11:$C407,MATCH($A17,'01_05_OMRI -2000'!$A11:$A407,0)) -> 3570 | AQ17: =AO17 -> 3570 | AS17: =N17/(K17+N17) -> 0.57894737 | AT17: =W17/(T17+W17) -> 0.56452793 | AU17: =AF17/(AC17+AF17) -> 0.6 | AV17: =AO17/(AL17+AO17) -> 0.62065369
A18: =A17+1 -> 46043 | B18: =INDEX('01_05_OMRI -2000'!$E$4:$E$393,MATCH($A18,'01_05_OMRI -2000'!$A$4:$A$393,0)) -> 62756 | D18: =B18 -> 62756 | E18: =INDEX('01_05_OMRI -2000'!$D$4:$D$393,MATCH($A18,'01_05_OMRI -2000'!$A$4:$A$393,0)) -> 2554 | G18: =E18 -> 2554 | H18: =-6250 -> -6250 | J18: =H18 -> -6250 | K18: =INDEX('01_05_OMRI -6250'!$B19:$B415,MATCH($A18,'01_05_OMRI -6250'!$A19:$A415,0)) -> 6400 | M18: =K18 -> 6400 | N18: =INDEX('01_05_OMRI -6250'!$C19:$C415,MATCH($A18,'01_05_OMRI -6250'!$A19:$A415,0)) -> 8800 | P18: =N18 -> 8800 | Q18: -5000 | S18: =Q18 -> -5000 | T18: =INDEX('01_05_OMRI -5000'!$B12:$B408,MATCH($A18,'01_05_OMRI -5000'!$A12:$A408,0)) -> 5355 | V18: =T18 -> 5355 | W18: =INDEX('01_05_OMRI -5000'!$C12:$C408,MATCH($A18,'01_05_OMRI -5000'!$A12:$A408,0)) -> 6942 | Y18: =W18 -> 6942 | Z18: -3500 | AB18: =Z18 -> -3500 | AC18: =INDEX('01_05_OMRI -3500'!$B12:$B408,MATCH($A18,'01_05_OMRI -3500'!$A12:$A408,0)) -> 3570 | AE18: =AC18 -> 3570 | AF18: =INDEX('01_05_OMRI -3500'!$C12:$C408,MATCH($A18,'01_05_OMRI -3500'!$A12:$A408,0)) -> 5355 | AH18: =AF18 -> 5355 | AI18: -2000 | AK18: =AI18 -> -2000 | AL18: =INDEX('01_05_OMRI -2000'!$B12:$B408,MATCH($A18,'01_05_OMRI -2000'!$A12:$A408,0)) -> 2182 | AN18: =AL18 -> 2182 | AO18: =INDEX('01_05_OMRI -2000'!$C12:$C408,MATCH($A18,'01_05_OMRI -2000'!$A12:$A408,0)) -> 3570 | AQ18: =AO18 -> 3570 | AS18: =N18/(K18+N18) -> 0.57894737 | AT18: =W18/(T18+W18) -> 0.56452793 | AU18: =AF18/(AC18+AF18) -> 0.6 | AV18: =AO18/(AL18+AO18) -> 0.62065369
A19: =A18+1 -> 46044 | B19: =INDEX('01_05_OMRI -2000'!$E$4:$E$393,MATCH($A19,'01_05_OMRI -2000'!$A$4:$A$393,0)) -> 62756 | D19: =B19 -> 62756 | E19: =INDEX('01_05_OMRI -2000'!$D$4:$D$393,MATCH($A19,'01_05_OMRI -2000'!$A$4:$A$393,0)) -> 2554 | G19: =E19 -> 2554 | H19: =-6250 -> -6250 | J19: =H19 -> -6250 | K19: =INDEX('01_05_OMRI -6250'!$B20:$B416,MATCH($A19,'01_05_OMRI -6250'!$A20:$A416,0)) -> 6400 | M19: =K19 -> 6400 | N19: =INDEX('01_05_OMRI -6250'!$C20:$C416,MATCH($A19,'01_05_OMRI -6250'!$A20:$A416,0)) -> 8800 | P19: =N19 -> 8800 | Q19: -5000 | S19: =Q19 -> -5000 | T19: =INDEX('01_05_OMRI -5000'!$B13:$B409,MATCH($A19,'01_05_OMRI -5000'!$A13:$A409,0)) -> 5355 | V19: =T19 -> 5355 | W19: =INDEX('01_05_OMRI -5000'!$C13:$C409,MATCH($A19,'01_05_OMRI -5000'!$A13:$A409,0)) -> 6942 | Y19: =W19 -> 6942 | Z19: -3500 | AB19: =Z19 -> -3500 | AC19: =INDEX('01_05_OMRI -3500'!$B13:$B409,MATCH($A19,'01_05_OMRI -3500'!$A13:$A409,0)) -> 3570 | AE19: =AC19 -> 3570 | AF19: =INDEX('01_05_OMRI -3500'!$C13:$C409,MATCH($A19,'01_05_OMRI -3500'!$A13:$A409,0)) -> 5355 | AH19: =AF19 -> 5355 | AI19: -2000 | AK19: =AI19 -> -2000 | AL19: =INDEX('01_05_OMRI -2000'!$B13:$B409,MATCH($A19,'01_05_OMRI -2000'!$A13:$A409,0)) -> 2182 | AN19: =AL19 -> 2182 | AO19: =INDEX('01_05_OMRI -2000'!$C13:$C409,MATCH($A19,'01_05_OMRI -2000'!$A13:$A409,0)) -> 3570 | AQ19: =AO19 -> 3570 | AS19: =N19/(K19+N19) -> 0.57894737 | AT19: =W19/(T19+W19) -> 0.56452793 | AU19: =AF19/(AC19+AF19) -> 0.6 | AV19: =AO19/(AL19+AO19) -> 0.62065369
A20: =A19+1 -> 46045 | B20: =INDEX('01_05_OMRI -2000'!$E$4:$E$393,MATCH($A20,'01_05_OMRI -2000'!$A$4:$A$393,0)) -> 62756 | D20: =B20 -> 62756 | E20: =INDEX('01_05_OMRI -2000'!$D$4:$D$393,MATCH($A20,'01_05_OMRI -2000'!$A$4:$A$393,0)) -> 2555 | G20: =E20 -> 2555 | H20: =-6250 -> -6250 | J20: =H20 -> -6250 | K20: =INDEX('01_05_OMRI -6250'!$B21:$B417,MATCH($A20,'01_05_OMRI -6250'!$A21:$A417,0)) -> 6400 | M20: =K20 -> 6400 | N20: =INDEX('01_05_OMRI -6250'!$C21:$C417,MATCH($A20,'01_05_OMRI -6250'!$A21:$A417,0)) -> 8800 | P20: =N20 -> 8800 | Q20: -5000 | S20: =Q20 -> -5000 | T20: =INDEX('01_05_OMRI -5000'!$B14:$B410,MATCH($A20,'01_05_OMRI -5000'!$A14:$A410,0)) -> 5355 | V20: =T20 -> 5355 | W20: =INDEX('01_05_OMRI -5000'!$C14:$C410,MATCH($A20,'01_05_OMRI -5000'!$A14:$A410,0)) -> 6942 | Y20: =W20 -> 6942 | Z20: -3500 | AB20: =Z20 -> -3500 | AC20: =INDEX('01_05_OMRI -3500'!$B14:$B410,MATCH($A20,'01_05_OMRI -3500'!$A14:$A410,0)) -> 3570 | AE20: =AC20 -> 3570 | AF20: =INDEX('01_05_OMRI -3500'!$C14:$C410,MATCH($A20,'01_05_OMRI -3500'!$A14:$A410,0)) -> 5355 | AH20: =AF20 -> 5355 | AI20: -2000 | AK20: =AI20 -> -2000 | AL20: =INDEX('01_05_OMRI -2000'!$B14:$B410,MATCH($A20,'01_05_OMRI -2000'!$A14:$A410,0)) -> 2182 | AN20: =AL20 -> 2182 | AO20: =INDEX('01_05_OMRI -2000'!$C14:$C410,MATCH($A20,'01_05_OMRI -2000'!$A14:$A410,0)) -> 3570 | AQ20: =AO20 -> 3570 | AS20: =N20/(K20+N20) -> 0.57894737 | AT20: =W20/(T20+W20) -> 0.56452793 | AU20: =AF20/(AC20+AF20) -> 0.6 | AV20: =AO20/(AL20+AO20) -> 0.62065369
A21: =A20+1 -> 46046 | B21: =INDEX('01_05_OMRI -2000'!$E$4:$E$393,MATCH($A21,'01_05_OMRI -2000'!$A$4:$A$393,0)) -> 62756 | D21: =B21 -> 62756 | E21: =INDEX('01_05_OMRI -2000'!$D$4:$D$393,MATCH($A21,'01_05_OMRI -2000'!$A$4:$A$393,0)) -> 2555 | G21: =E21 -> 2555 | H21: =-6250 -> -6250 | J21: =H21 -> -6250 | K21: =INDEX('01_05_OMRI -6250'!$B22:$B418,MATCH($A21,'01_05_OMRI -6250'!$A22:$A418,0)) -> 6400 | M21: =K21 -> 6400 | N21: =INDEX('01_05_OMRI -6250'!$C22:$C418,MATCH($A21,'01_05_OMRI -6250'!$A22:$A418,0)) -> 8800 | P21: =N21 -> 8800 | Q21: -5000 | S21: =Q21 -> -5000 | T21: =INDEX('01_05_OMRI -5000'!$B15:$B411,MATCH($A21,'01_05_OMRI -5000'!$A15:$A411,0)) -> 5355 | V21: =T21 -> 5355 | W21: =INDEX('01_05_OMRI -5000'!$C15:$C411,MATCH($A21,'01_05_OMRI -5000'!$A15:$A411,0)) -> 6942 | Y21: =W21 -> 6942 | Z21: -3500 | AB21: =Z21 -> -3500 | AC21: =INDEX('01_05_OMRI -3500'!$B15:$B411,MATCH($A21,'01_05_OMRI -3500'!$A15:$A411,0)) -> 3570 | AE21: =AC21 -> 3570 | AF21: =INDEX('01_05_OMRI -3500'!$C15:$C411,MATCH($A21,'01_05_OMRI -3500'!$A15:$A411,0)) -> 5355 | AH21: =AF21 -> 5355 | AI21: -2000 | AK21: =AI21 -> -2000 | AL21: =INDEX('01_05_OMRI -2000'!$B15:$B411,MATCH($A21,'01_05_OMRI -2000'!$A15:$A411,0)) -> 2182 | AN21: =AL21 -> 2182 | AO21: =INDEX('01_05_OMRI -2000'!$C15:$C411,MATCH($A21,'01_05_OMRI -2000'!$A15:$A411,0)) -> 3570 | AQ21: =AO21 -> 3570 | AS21: =N21/(K21+N21) -> 0.57894737 | AT21: =W21/(T21+W21) -> 0.56452793 | AU21: =AF21/(AC21+AF21) -> 0.6 | AV21: =AO21/(AL21+AO21) -> 0.62065369
... A24: =A23+1 -> 46049 | B24: =INDEX('01_05_OMRI -2000'!$E$4:$E$393,MATCH($A24,'01_05_OMRI -2000'!$A$4:$A$393,0)) -> 62756 | D24: =B24 -> 62756 | E24: =INDEX('01_05_OMRI -2000'!$D$4:$D$393,MATCH($A24,'01_05_OMRI -2000'!$A$4:$A$393,0)) -> 2556 | G24: =E24 -> 2556 | H24: =-6250 -> -6250 | J24: =H24 -> -6250 | K24: =INDEX('01_05_OMRI -6250'!$B25:$B421,MATCH($A24,'01_05_OMRI -6250'!$A25:$A421,0)) -> 6400 | M24: =K24 -> 6400 | N24: =INDEX('01_05_OMRI -6250'!$C25:$C421,MATCH($A24,'01_05_OMRI -6250'!$A25:$A421,0)) -> 8800 | P24: =N24 -> 8800 | Q24: -5000 | S24: =Q24 -> -5000 | T24: =INDEX('01_05_OMRI -5000'!$B18:$B414,MATCH($A24,'01_05_OMRI -5000'!$A18:$A414,0)) -> 5355 | V24: =T24 -> 5355 | W24: =INDEX('01_05_OMRI -5000'!$C18:$C414,MATCH($A24,'01_05_OMRI -5000'!$A18:$A414,0)) -> 6942 | Y24: =W24 -> 6942 | Z24: -3500 | AB24: =Z24 -> -3500 | AC24: =INDEX('01_05_OMRI -3500'!$B18:$B414,MATCH($A24,'01_05_OMRI -3500'!$A18:$A414,0)) -> 3570 | AE24: =AC24 -> 3570 | AF24: =INDEX('01_05_OMRI -3500'!$C18:$C414,MATCH($A24,'01_05_OMRI -3500'!$A18:$A414,0)) -> 5355 | AH24: =AF24 -> 5355 | AI24: -2000 | AK24: =AI24 -> -2000 | AL24: =INDEX('01_05_OMRI -2000'!$B18:$B414,MATCH($A24,'01_05_OMRI -2000'!$A18:$A414,0)) -> 2182 | AN24: =AL24 -> 2182 | AO24: =INDEX('01_05_OMRI -2000'!$C18:$C414,MATCH($A24,'01_05_OMRI -2000'!$A18:$A414,0)) -> 3570 | AQ24: =AO24 -> 3570 | AS24: =N24/(K24+N24) -> 0.57894737 | AT24: =W24/(T24+W24) -> 0.56452793 | AU24: =AF24/(AC24+AF24) -> 0.6 | AV24: =AO24/(AL24+AO24) -> 0.62065369
K25: =AVERAGE(K3:K24) -> 6777.2727 | N25: =AVERAGE(N3:N24) -> 8873.6364 | T25: =AVERAGE(T3:T24) -> 5598.5 | W25: =AVERAGE(W3:W24) -> 7131.4091 | AC25: =AVERAGE(AC3:AC24) -> 3894.6364 | AF25: =AVERAGE(AF3:AF24) -> 5571.4091 | AL25: =AVERAGE(AL3:AL24) -> 2551.6364 | AO25: =AVERAGE(AO3:AO24) -> 3804.4091
Z33: Thresholds
T34: Sacramento River at Freeport (cfs) | V34: San Joaquin River at Vernalis (cfs) | AB34: Sacramento River at Freeport (cfs) | AC34: Flow bin | AD34: San Joaquin River at Vernalis (cfs)
R35: Week 1 | S35: =_xlfn.CONCAT(R35," (",TEXT(A3,"mm/dd/yyyy")," - ",TEXT(A9,"mm/dd/yyyy"),")") -> Week 1 (01/06/2026 - 01/12/2026) | T35: =AVERAGE(B3:B9) -> 72987.143 | U35: =IF(T35<=$AB$35,$AC$35,IF(T35>=$AB$37,$AC$37,$AC$36)) -> hi | V35: =AVERAGE(E3:E9) -> 3590.8571 | W35: =IF(V35<=$AD$35,$AC$35,IF(V35>=$AD$37,$AC$37,$AC$36)) -> med | X35: =_xlfn.CONCAT(U35,W35) -> himed | AA35: <= | AB35: 13145 | AC35: lo | AD35: 1983
R36: Week 2 | S36: =_xlfn.CONCAT(R36," (",TEXT(A10,"mm/dd/yyyy")," - ",TEXT(A16,"mm/dd/yyyy"),")") -> Week 2 (01/13/2026 - 01/19/2026) | T36: =AVERAGE(B10:B16) -> 63254.429 | U36: =IF(T36<=$AB$35,$AC$35,IF(T36>=$AB$37,$AC$37,$AC$36)) -> hi | V36: =AVERAGE(E10:E16) -> 2551.8571 | W36: =IF(V36<=$AD$35,$AC$35,IF(V36>=$AD$37,$AC$37,$AC$36)) -> med | X36: =_xlfn.CONCAT(U36,W36) -> himed | AB36: 24725 | AC36: med | AD36: 4096
R37: Week 3 | S37: =_xlfn.CONCAT(R37," (",TEXT(A17,"mm/dd/yyyy")," - ",TEXT(A23,"mm/dd/yyyy"),")") -> Week 3 (01/20/2026 - 01/26/2026) | T37: =AVERAGE(B18:B24) -> 62756 | U37: =IF(T37<=$AB$35,$AC$35,IF(T37>=$AB$37,$AC$37,$AC$36)) -> hi | V37: =AVERAGE(E18:E24) -> 2555 | W37: =IF(V37<=$AD$35,$AC$35,IF(V37>=$AD$37,$AC$37,$AC$36)) -> med | X37: =_xlfn.CONCAT(U37,W37) -> himed | AA37: >= | AB37: 24726 | AC37: hi | AD37: 4097
T41: OMR Bins | U41: CVP Exports (AF) | V41: SWP Exports (AF) | W41: Total Exports (AF) | X41: CVP Exports (% of total) | Y41: SWP Exports (% of total))
S42: Week 1 | T42: -6250 | U42: =AVERAGE(N3:N9) -> 9031.4286 | V42: =AVERAGE(K3:K9) -> 7585.7143 | W42: =V42+U42 -> 16617.143 | X42: =U42/(U42+V42) -> 0.54350069 | Y42: =V42/(V42+U42) -> 0.45649931 | AA42: =W42/1.98 -> 8392.4964
T43: -5000 | U43: =AVERAGE(W3:W9) -> 7537.2857 | V43: =AVERAGE(T3:T9) -> 6120.2857 | W43: =V43+U43 -> 13657.571 | X43: =U43/(U43+V43) -> 0.55187599 | Y43: =V43/(V43+U43) -> 0.44812401 | AA43: =W43/1.98 -> 6897.7633
T44: -3250 | U44: =AVERAGE(AF3:AF9) -> 6035.1429 | V44: =AVERAGE(AC3:AC9) -> 4590.2857 | W44: =V44+U44 -> 10625.429 | X44: =U44/(U44+V44) -> 0.56799053 | Y44: =V44/(V44+U44) -> 0.43200947 | AA44: =W44/1.98 -> 5366.3781
T45: -2000 | U45: =AVERAGE(AO3:AO9) -> 4306.7143 | V45: =AVERAGE(AL3:AL9) -> 3343.7143 | W45: =V45+U45 -> 7650.4286 | X45: =U45/(U45+V45) -> 0.56293765 | Y45: =V45/(V45+U45) -> 0.43706235 | AA45: =W45/1.98 -> 3863.8528
S46: Week 2 | T46: -6250 | U46: =AVERAGE(N10:N16) -> 8800 | V46: =AVERAGE(K10:K16) -> 6400 | W46: =V46+U46 -> 15200 | X46: =U46/(U46+V46) -> 0.57894737 | Y46: =V46/(V46+U46) -> 0.42105263 | AA46: =W46/1.98 -> 7676.7677
T47: -5000 | U47: =AVERAGE(W10:W16) -> 6942 | V47: =AVERAGE(T10:T16) -> 5355 | W47: =V47+U47 -> 12297 | X47: =U47/(U47+V47) -> 0.56452793 | Y47: =V47/(V47+U47) -> 0.43547207 | AA47: =W47/1.98 -> 6210.6061
T48: -3250 | U48: =AVERAGE(AF10:AF16) -> 5355 | V48: =AVERAGE(AC10:AC16) -> 3570 | W48: =V48+U48 -> 8925 | X48: =U48/(U48+V48) -> 0.6 | Y48: =V48/(V48+U48) -> 0.4 | AA48: =W48/1.98 -> 4507.5758
T49: -2000 | U49: =AVERAGE(AO10:AO16) -> 3570 | V49: =AVERAGE(AL10:AL16) -> 2182 | W49: =V49+U49 -> 5752 | X49: =U49/(U49+V49) -> 0.62065369 | Y49: =V49/(V49+U49) -> 0.37934631 | AA49: =W49/1.98 -> 2905.0505
S50: Week 3 | T50: -6250 | U50: =AVERAGE(N18:N24) -> 8800 | V50: =AVERAGE(K18:K24) -> 6400 | W50: =V50+U50 -> 15200 | X50: =U50/(U50+V50) -> 0.57894737 | Y50: =V50/(V50+U50) -> 0.42105263 | AA50: =W50/1.98 -> 7676.7677
T51: -5000 | U51: =AVERAGE(N19:N25) -> 8810.5195 | V51: =AVERAGE(T18:T24) -> 5355 | W51: =V51+U51 -> 14165.519 | X51: =U51/(U51+V51) -> 0.62196939 | Y51: =V51/(V51+U51) -> 0.37803061 | AA51: =W51/1.98 -> 7154.3028
T52: -3250 | U52: =AVERAGE(N20:N26) -> 8812.2727 | V52: =AVERAGE(AC18:AC24) -> 3570 | W52: =V52+U52 -> 12382.273 | X52: =U52/(U52+V52) -> 0.71168459 | Y52: =V52/(V52+U52) -> 0.28831541 | AA52: =W52/1.98 -> 6253.6731
...

Sheet 01_05_OMRI -2000
A1: Forecast start date | D1: VNS-QR | E1: FPT-QR | K1: data type | M1: Data request: | O1: Updated 1/8/2026 by Stantec. Added measured data from 1/5/2026 to 1/7/2026, adjusted forecast.
A2: 46027 | B2: af | C2: af | D2: cfs | E2: cfs | F2: cfs | G2: cfs | H2: cfs | I2: cfs | J2: cfs | M2: 31 days of historical measured data prior to forecast date
A3: DATE | B3: CCF | C3: TPP | D3: VNS | E3: FPT | F3: CAL | G3: MOKE | H3: COS | I3: SACWEIR | J3: FREWEIR | M3: 14 days of forecast data after forecast date
A4: 46003 | B4: 3952 | C4: 1915 | D4: 1161 | E4: 9935 | F4: 24 | G4: 284 | H4: 76.6 | I4: 0 | J4: 0 | K4: Measured
A5: 46004 | B5: 3956 | C5: 1919 | D5: 1133 | E5: 9724 | F5: 24 | G5: 312 | H5: 76 | I5: 0 | J5: 0 | K5: Measured
A6: 46005 | B6: 3963 | C6: 1922 | D6: 1125 | E6: 9847 | F6: 24 | G6: 319 | H6: 75.2 | I6: 0 | J6: 0 | K6: Measured
A7: 46006 | B7: 3960 | C7: 1829 | D7: 1121 | E7: 10204 | F7: 24 | G7: 290 | H7: 74.1 | I7: 0 | J7: 0 | K7: Measured
A8: 46007 | B8: 3172 | C8: 1922 | D8: 1096 | E8: 10492 | F8: 24 | G8: 269 | H8: 73.8 | I8: 0 | J8: 0 | K8: Measured
A9: 46008 | B9: 3147 | C9: 1924 | D9: 1071 | E9: 10806 | F9: 24 | G9: 280 | H9: 75.5 | I9: 0 | J9: 0 | K9: Measured
A10: 46009 | B10: 3965 | C10: 1927 | D10: 1092 | E10: 11679 | F10: 24 | G10: 284 | H10: 82 | I10: 0 | J10: 0 | K10: Measured
A11: 46010 | B11: 5931 | C11: 1949 | D11: 1747 | E11: 13236 | F11: 91 | G11: 281 | H11: 89.7 | I11: 0 | J11: 0 | K11: Measured
A12: 46011 | B12: 10880 | C12: 5275 | D12: 3558 | E12: 18038 | F12: 150 | G12: 281 | H12: 97.5 | I12: 0 | J12: 0 | K12: Measured
A13: 46012 | B13: 12873 | C13: 6992 | D13: 4848 | E13: 20977 | F13: 150 | G13: 283 | H13: 166 | I13: 0 | J13: 0 | K13: Measured
A14: 46013 | B14: 10892 | C14: 7004 | D14: 5822 | E14: 33157 | F14: 150 | G14: 304 | H14: 552 | I14: 0 | J14: 0 | K14: Measured
A15: 46014 | B15: 14865 | C15: 8224 | D15: 6068 | E15: 47908 | F15: 151 | G15: 281 | H15: 1040 | I15: 0 | J15: 0 | K15: Measured
... A43: 46042 | B43: 2182 | C43: 3570 | D43: 2553 | E43: 62756 | F43: 250 | G43: 300 | H43: 500 | I43: 0 | J43: 50066 | K43: Forecasted
A44: =A43+1 -> 46043 | B44: 2182 | C44: 3570 | D44: 2554 | E44: 62756 | F44: 250 | G44: 300 | H44: 500 | I44: 0 | J44: 50066 | K44: Forecasted
A45: =A44+1 -> 46044 | B45: 2182 | C45: 3570 | D45: 2554 | E45: 62756 | F45: 250 | G45: 300 | H45: 500 | I45: 0 | J45: 50066 | K45: Forecasted
A46: =A45+1 -> 46045 | B46: 2182 | C46: 3570 | D46: 2555 | E46: 62756 | F46: 250 | G46: 300 | H46: 500 | I46: 0 | J46: 50066 | K46: Forecasted
A47: =A46+1 -> 46046 | B47: 2182 | C47: 3570 | D47: 2555 | E47: 62756 | F47: 250 | G47: 300 | H47: 500 | I47: 0 | J47: 50066 | K47: Forecasted
A48: =A47+1 -> 46047 | B48: 2182 | C48: 3570 | D48: 2555 | E48: 62756 | F48: 250 | G48: 300 | H48: 500 | I48: 0 | J48: 50066 | K48: Forecasted
A49: =A48+1 -> 46048 | B49: 2182 | C49: 3570 | D49: 2556 | E49: 62756 | F49: 250 | G49: 300 | H49: 500 | I49: 0 | J49: 50066 | K49: Forecasted
A50: =A49+1 -> 46049 | B50: 2182 | C50: 3570 | D50: 2556 | E50: 62756 | F50: 250 | G50: 300 | H50: 500 | I50: 0 | J50: 50066 | K50: Forecasted

Sheet 01_05_OMRI -3500
A1: Forecast start date | D1: VNS-QR | E1: FPT-QR | K1: data type | M1: Data request: | O1: Updated 1/8/2026 by Stantec. Added measured data from 1/5/2026 to 1/7/2026, adjusted forecast.
A2: 46027 | B2: af | C2: af | D2: cfs | E2: cfs | F2: cfs | G2: cfs | H2: cfs | I2: cfs | J2: cfs | M2: 31 days of historical measured data prior to forecast date
A3: DATE | B3: CCF | C3: TPP | D3: VNS | E3: FPT | F3: CAL | G3: MOKE | H3: COS | I3: SACWEIR | J3: FREWEIR | M3: 14 days of forecast data after forecast date
A4: 46003 | B4: 3952 | C4: 1915 | D4: 1161 | E4: 9935 | F4: 24 | G4: 284 | H4: 76.6 | I4: 0 | J4: 0 | K4: Measured
A5: 46004 | B5: 3956 | C5: 1919 | D5: 1133 | E5: 9724 | F5: 24 | G5: 312 | H5: 76 | I5: 0 | J5: 0 | K5: Measured
A6: 46005 | B6: 3963 | C6: 1922 | D6: 1125 | E6: 9847 | F6: 24 | G6: 319 | H6: 75.2 | I6: 0 | J6: 0 | K6: Measured
A7: 46006 | B7: 3960 | C7: 1829 | D7: 1121 | E7: 10204 | F7: 24 | G7: 290 | H7: 74.1 | I7: 0 | J7: 0 | K7: Measured
A8: 46007 | B8: 3172 | C8: 1922 | D8: 1096 | E8: 10492 | F8: 24 | G8: 269 | H8: 73.8 | I8: 0 | J8: 0 | K8: Measured
A9: 46008 | B9: 3147 | C9: 1924 | D9: 1071 | E9: 10806 | F9: 24 | G9: 280 | H9: 75.5 | I9: 0 | J9: 0 | K9: Measured
A10: 46009 | B10: 3965 | C10: 1927 | D10: 1092 | E10: 11679 | F10: 24 | G10: 284 | H10: 82 | I10: 0 | J10: 0 | K10: Measured
A11: 46010 | B11: 5931 | C11: 1949 | D11: 1747 | E11: 13236 | F11: 91 | G11: 281 | H11: 89.7 | I11: 0 | J11: 0 | K11: Measured
A12: 46011 | B12: 10880 | C12: 5275 | D12: 3558 | E12: 18038 | F12: 150 | G12: 281 | H12: 97.5 | I12: 0 | J12: 0 | K12: Measured
A13: 46012 | B13: 12873 | C13: 6992 | D13: 4848 | E13: 20977 | F13: 150 | G13: 283 | H13: 166 | I13: 0 | J13: 0 | K13: Measured
A14: 46013 | B14: 10892 | C14: 7004 | D14: 5822 | E14: 33157 | F14: 150 | G14: 304 | H14: 552 | I14: 0 | J14: 0 | K14: Measured
A15: 46014 | B15: 14865 | C15: 8224 | D15: 6068 | E15: 47908 | F15: 151 | G15: 281 | H15: 1040 | I15: 0 | J15: 0 | K15: Measured
... A50: 46049 | B50: 3570 | C50: 5355 | D50: 2556 | E50: 62756 | F50: 250 | G50: 300 | H50: 500 | I50: 0 | J50: 50066 | K50: Forecasted

Sheet 01_05_OMRI -5000
A1: Forecast start date | D1: VNS-QR | E1: FPT-QR | K1: data type | M1: Data request: | O1: Updated 1/8/2026 by Stantec. Added measured data from 1/5/2026 to 1/7/2026, adjusted forecast.
A2: 46027 | B2: af | C2: af | D2: cfs | E2: cfs | F2: cfs | G2: cfs | H2: cfs | I2: cfs | J2: cfs | M2: 31 days of historical measured data prior to forecast date
A3: DATE | B3: CCF | C3: TPP | D3: VNS | E3: FPT | F3: CAL | G3: MOKE | H3: COS | I3: SACWEIR | J3: FREWEIR | M3: 14 days of forecast data after forecast date
A4: 46003 | B4: 3952 | C4: 1915 | D4: 1161 | E4: 9935 | F4: 24 | G4: 284 | H4: 76.6 | I4: 0 | J4: 0 | K4: Measured
A5: 46004 | B5: 3956 | C5: 1919 | D5: 1133 | E5: 9724 | F5: 24 | G5: 312 | H5: 76 | I5: 0 | J5: 0 | K5: Measured
A6: 46005 | B6: 3963 | C6: 1922 | D6: 1125 | E6: 9847 | F6: 24 | G6: 319 | H6: 75.2 | I6: 0 | J6: 0 | K6: Measured
A7: 46006 | B7: 3960 | C7: 1829 | D7: 1121 | E7: 10204 | F7: 24 | G7: 290 | H7: 74.1 | I7: 0 | J7: 0 | K7: Measured
A8: 46007 | B8: 3172 | C8: 1922 | D8: 1096 | E8: 10492 | F8: 24 | G8: 269 | H8: 73.8 | I8: 0 | J8: 0 | K8: Measured
A9: 46008 | B9: 3147 | C9: 1924 | D9: 1071 | E9: 10806 | F9: 24 | G9: 280 | H9: 75.5 | I9: 0 | J9: 0 | K9: Measured
A10: 46009 | B10: 3965 | C10: 1927 | D10: 1092 | E10: 11679 | F10: 24 | G10: 284 | H10: 82 | I10: 0 | J10: 0 | K10: Measured
A11: 46010 | B11: 5931 | C11: 1949 | D11: 1747 | E11: 13236 | F11: 91 | G11: 281 | H11: 89.7 | I11: 0 | J11: 0 | K11: Measured
A12: 46011 | B12: 10880 | C12: 5275 | D12: 3558 | E12: 18038 | F12: 150 | G12: 281 | H12: 97.5 | I12: 0 | J12: 0 | K12: Measured
A13: 46012 | B13: 12873 | C13: 6992 | D13: 4848 | E13: 20977 | F13: 150 | G13: 283 | H13: 166 | I13: 0 | J13: 0 | K13: Measured
A14: 46013 | B14: 10892 | C14: 7004 | D14: 5822 | E14: 33157 | F14: 150 | G14: 304 | H14: 552 | I14: 0 | J14: 0 | K14: Measured
A15: 46014 | B15: 14865 | C15: 8224 | D15: 6068 | E15: 47908 | F15: 151 | G15: 281 | H15: 1040 | I15: 0 | J15: 0 | K15: Measured
... A50: 46049 | B50: 5355 | C50: 6942 | D50: 2556 | E50: 62756 | F50: 250 | G50: 300 | H50: 500 | I50: 0 | J50: 50066 | K50: Forecasted

Sheet 01_05_OMRI -6250
A1: Forecast start date | D1: VNS-QR | E1: FPT-QR | K1: data type | M1: Data request: | O1: Updated 1/8/2026 by Stantec. Added measured data from 1/5/2026 to 1/7/2026, adjusted forecast.
A2: 46030 | B2: af | C2: af | D2: cfs | E2: cfs | F2: cfs | G2: cfs | H2: cfs | I2: cfs | J2: cfs | M2: 31 days of historical measured data prior to forecast date
A3: DATE | B3: CCF | C3: TPP | D3: VNS | E3: FPT | F3: CAL | G3: MOKE | H3: COS | I3: SACWEIR | J3: FREWEIR | M3: 14 days of forecast data after forecast date
A4: 46003 | B4: 3952 | C4: 1915 | D4: 1161 | E4: 9935 | F4: 24 | G4: 284 | H4: 76.6 | I4: 0 | J4: 0 | K4: Measured
A5: 46004 | B5: 3956 | C5: 1919 | D5: 1133 | E5: 9724 | F5: 24 | G5: 312 | H5: 76 | I5: 0 | J5: 0 | K5: Measured
A6: 46005 | B6: 3963 | C6: 1922 | D6: 1125 | E6: 9847 | F6: 24 | G6: 319 | H6: 75.2 | I6: 0 | J6: 0 | K6: Measured
A7: 46006 | B7: 3960 | C7: 1829 | D7: 1121 | E7: 10204 | F7: 24 | G7: 290 | H7: 74.1 | I7: 0 | J7: 0 | K7: Measured
A8: 46007 | B8: 3172 | C8: 1922 | D8: 1096 | E8: 10492 | F8: 24 | G8: 269 | H8: 73.8 | I8: 0 | J8: 0 | K8: Measured
A9: 46008 | B9: 3147 | C9: 1924 | D9: 1071 | E9: 10806 | F9: 24 | G9: 280 | H9: 75.5 | I9: 0 | J9: 0 | K9: Measured
A10: 46009 | B10: 3965 | C10: 1927 | D10: 1092 | E10: 11679 | F10: 24 | G10: 284 | H10: 82 | I10: 0 | J10: 0 | K10: Measured
A11: 46010 | B11: 5931 | C11: 1949 | D11: 1747 | E11: 13236 | F11: 91 | G11: 281 | H11: 89.7 | I11: 0 | J11: 0 | K11: Measured
A12: 46011 | B12: 10880 | C12: 5275 | D12: 3558 | E12: 18038 | F12: 150 | G12: 281 | H12: 97.5 | I12: 0 | J12: 0 | K12: Measured
A13: 46012 | B13: 12873 | C13: 6992 | D13: 4848 | E13: 20977 | F13: 150 | G13: 283 | H13: 166 | I13: 0 | J13: 0 | K13: Measured
A14: 46013 | B14: 10892 | C14: 7004 | D14: 5822 | E14: 33157 | F14: 150 | G14: 304 | H14: 552 | I14: 0 | J14: 0 | K14: Measured
A15: 46014 | B15: 14865 | C15: 8224 | D15: 6068 | E15: 47908 | F15: 151 | G15: 281 | H15: 1040 | I15: 0 | J15: 0 | K15: Measured
... A50: 46049 | B50: 6400 | C50: 8800 | D50: 2556 | E50: 62756 | F50: 250 | G50: 300 | H50: 500 | I50: 0 | J50: 50066 | K50: Forecasted
